Workbook

Sheet Cómo se usa
C3: InnoSoft Days 2026
C5: Escaleta compartida del Comité de Dirección
C6: 14ª edición · 16, 17 y 18 de noviembre de 2026 · 50 aniversario de los estudios de Informática (1976–2026)
B11: Cómo funciona
B12: Escaleta | C12: Es la lista maestra. Una fila por actividad, reunión o plazo, de cualquier día del curso. Es lo único que se edita a mano.
B13: Hora fija | C13: Escríbela solo en la primera actividad del día o cuando algo deba empezar a una hora concreta. Si la dejas vacía, la actividad empieza cuando acaba la fila anterior del mismo día, así que cambiar una duración mueve todo lo que va detrás.
B14: Duración | C14: En minutos exactos (7, 12, 45…). Inicio y Fin se calculan solos.
B15: Aviso | C15: Sale en rojo si dos actividades no canceladas ocupan la misma sala a la vez.
B16: Cuadrícula | C16: Elige un día en la celda amarilla y verás cada sala como una columna, en franjas del tamaño que marques en Configuración (5, 10, 15, 30 o 60 min).
B17: Configuración | C17: Comités, coordinación, salas, estados, tipos y horario del día. Las salas y los días que añadas aparecen solos en los desplegables y en la cuadrícula.
B18: Notas | C18: Usa la columna Notas para el detalle de cada franja, y los comentarios de Google Sheets (mencionando con @) para preguntar o avisar a alguien.
B21: Comités
C22: Dirección / Presidencia | D22: =IF(Configuración!$C$12="","Por asignar",Configuración!$C$12)
C23: Secretaría General | D23: =IF(Configuración!$C$13="","Por asignar",Configuración!$C$13)
C24: Programa | D24: =IF(Configuración!$C$14="","Por asignar",Configuración!$C$14)
C25: Logística | D25: =IF(Configuración!$C$15="","Por asignar",Configuración!$C$15)
C26: Comunicación | D26: =IF(Configuración!$C$16="","Por asignar",Configuración!$C$16)
C27: Finanzas | D27: =IF(Configuración!$C$17="","Por asignar",Configuración!$C$17)
C28: Igualdad y Sostenibilidad | D28: =IF(Configuración!$C$18="","Por asignar",Configuración!$C$18)
B31: Estados
C32: Borrador | D32: Idea en preparación, aún no se ha propuesto
C33: Pendiente de visto bueno | D33: Propuesta enviada a Presidencia, esperando visto bueno
C34: Confirmada | D34: Aprobada y lista para anunciar
C35: Cancelada | D35: Se mantiene para el historial, no ocupa sala
B38: Para cambiar un color o el nombre de un comité o estado: Formato > Formato condicional en las hojas Escaleta y Cuadrícula.

Sheet Escaleta
A1: InnoSoft Days 2026 · Escaleta | K1: 14ª edición · 50 aniversario de los estudios de Informática
A3: Una fila por actividad. Si dejas vacía la «Hora fija», empieza justo cuando termina la fila anterior del mismo día. Las columnas en gris se calculan solas.
A4: Día | B4: Hora fija | C4: Inicio | D4: Duración (min) | E4: Fin | F4: Actividad | G4: Tipo | H4: Sala | I4: Comité | J4: Responsable | K4: Estado | L4: Notas | M4: Aviso
A5: 46342 | B5: 0.375 | C5: =IF($A5="","",IF($B5<>"",$B5,IF($A5=$A4,$E4,Configuración!$C$5))) | D5: 30 | E5: =IF(OR($C5="",$D5=""),"",$C5+$D5/1440) | F5: Acreditación y bienvenida | G5: Otro | H5: Hall | I5: Logística | J5: Coordinación de Logística | K5: Borrador | L5: Fila de ejemplo: sustitúyela por la actividad real | M5: =IF(OR($C5="",$E5="",$H5="",$K5="Cancelada"),"",IF(COUNTIFS($A$5:$A$504,$A5,$H$5:$H$504,$H5,$K$5:$K$504,"<>Cancelada",$C$5:$C$504,"<"&$E5,$E$5:$E$504,">"&$C5)>1,"Se solapa con otra actividad en esta sala",""))
A6: 46342 | C6: =IF($A6="","",IF($B6<>"",$B6,IF($A6=$A5,$E5,Configuración!$C$5))) | D6: 15 | E6: =IF(OR($C6="",$D6=""),"",$C6+$D6/1440) | F6: Apertura de las jornadas | G6: Otro | H6: Sala 1 | I6: Dirección / Presidencia | J6: Presidencia | K6: Borrador | L6: Fila de ejemplo: sustitúyela por la actividad real | M6: =IF(OR($C6="",$E6="",$H6="",$K6="Cancelada"),"",IF(COUNTIFS($A$5:$A$504,$A6,$H$5:$H$504,$H6,$K$5:$K$504,"<>Cancelada",$C$5:$C$504,"<"&$E6,$E$5:$E$504,">"&$C6)>1,"Se solapa con otra actividad en esta sala",""))
A7: 46342 | C7: =IF($A7="","",IF($B7<>"",$B7,IF($A7=$A6,$E6,Configuración!$C$5))) | D7: 50 | E7: =IF(OR($C7="",$D7=""),"",$C7+$D7/1440) | F7: Ponencia inaugural | G7: Ponencia | H7: Sala 1 | I7: Programa | J7: Coordinación de Programa | K7: Pendiente de visto bueno | L7: Fila de ejemplo: sustitúyela por la actividad real | M7: =IF(OR($C7="",$E7="",$H7="",$K7="Cancelada"),"",IF(COUNTIFS($A$5:$A$504,$A7,$H$5:$H$504,$H7,$K$5:$K$504,"<>Cancelada",$C$5:$C$504,"<"&$E7,$E$5:$E$504,">"&$C7)>1,"Se solapa con otra actividad en esta sala",""))
C8: =IF($A8="","",IF($B8<>"",$B8,IF($A8=$A7,$E7,Configuración!$C$5))) | E8: =IF(OR($C8="",$D8=""),"",$C8+$D8/1440) | M8: =IF(OR($C8="",$E8="",$H8="",$K8="Cancelada"),"",IF(COUNTIFS($A$5:$A$504,$A8,$H$5:$H$504,$H8,$K$5:$K$504,"<>Cancelada",$C$5:$C$504,"<"&$E8,$E$5:$E$504,">"&$C8)>1,"Se solapa con otra actividad en esta sala",""))
C9: =IF($A9="","",IF($B9<>"",$B9,IF($A9=$A8,$E8,Configuración!$C$5))) | E9: =IF(OR($C9="",$D9=""),"",$C9+$D9/1440) | M9: =IF(OR($C9="",$E9="",$H9="",$K9="Cancelada"),"",IF(COUNTIFS($A$5:$A$504,$A9,$H$5:$H$504,$H9,$K$5:$K$504,"<>Cancelada",$C$5:$C$504,"<"&$E9,$E$5:$E$504,">"&$C9)>1,"Se solapa con otra actividad en esta sala",""))
C10: =IF($A10="","",IF($B10<>"",$B10,IF($A10=$A9,$E9,Configuración!$C$5))) | E10: =IF(OR($C10="",$D10=""),"",$C10+$D10/1440) | M10: =IF(OR($C10="",$E10="",$H10="",$K10="Cancelada"),"",IF(COUNTIFS($A$5:$A$504,$A10,$H$5:$H$504,$H10,$K$5:$K$504,"<>Cancelada",$C$5:$C$504,"<"&$E10,$E$5:$E$504,">"&$C10)>1,"Se solapa con otra actividad en esta sala",""))
C11: =IF($A11="","",IF($B11<>"",$B11,IF($A11=$A10,$E10,Configuración!$C$5))) | E11: =IF(OR($C11="",$D11=""),"",$C11+$D11/1440) | M11: =IF(OR($C11="",$E11="",$H11="",$K11="Cancelada"),"",IF(COUNTIFS($A$5:$A$504,$A11,$H$5:$H$504,$H11,$K$5:$K$504,"<>Cancelada",$C$5:$C$504,"<"&$E11,$E$5:$E$504,">"&$C11)>1,"Se solapa con otra actividad en esta sala",""))
C12: =IF($A12="","",IF($B12<>"",$B12,IF($A12=$A11,$E11,Configuración!$C$5))) | E12: =IF(OR($C12="",$D12=""),"",$C12+$D12/1440) | M12: =IF(OR($C12="",$E12="",$H12="",$K12="Cancelada"),"",IF(COUNTIFS($A$5:$A$504,$A12,$H$5:$H$504,$H12,$K$5:$K$504,"<>Cancelada",$C$5:$C$504,"<"&$E12,$E$5:$E$504,">"&$C12)>1,"Se solapa con otra actividad en esta sala",""))
C13: =IF($A13="","",IF($B13<>"",$B13,IF($A13=$A12,$E12,Configuración!$C$5))) | E13: =IF(OR($C13="",$D13=""),"",$C13+$D13/1440) | M13: =IF(OR($C13="",$E13="",$H13="",$K13="Cancelada"),"",IF(COUNTIFS($A$5:$A$504,$A13,$H$5:$H$504,$H13,$K$5:$K$504,"<>Cancelada",$C$5:$C$504,"<"&$E13,$E$5:$E$504,">"&$C13)>1,"Se solapa con otra actividad en esta sala",""))
C14: =IF($A14="","",IF($B14<>"",$B14,IF($A14=$A13,$E13,Configuración!$C$5))) | E14: =IF(OR($C14="",$D14=""),"",$C14+$D14/1440) | M14: =IF(OR($C14="",$E14="",$H14="",$K14="Cancelada"),"",IF(COUNTIFS($A$5:$A$504,$A14,$H$5:$H$504,$H14,$K$5:$K$504,"<>Cancelada",$C$5:$C$504,"<"&$E14,$E$5:$E$504,">"&$C14)>1,"Se solapa con otra actividad en esta sala",""))
C15: =IF($A15="","",IF($B15<>"",$B15,IF($A15=$A14,$E14,Configuración!$C$5))) | E15: =IF(OR($C15="",$D15=""),"",$C15+$D15/1440) | M15: =IF(OR($C15="",$E15="",$H15="",$K15="Cancelada"),"",IF(COUNTIFS($A$5:$A$504,$A15,$H$5:$H$504,$H15,$K$5:$K$504,"<>Cancelada",$C$5:$C$504,"<"&$E15,$E$5:$E$504,">"&$C15)>1,"Se solapa con otra actividad en esta sala",""))
C16: =IF($A16="","",IF($B16<>"",$B16,IF($A16=$A15,$E15,Configuración!$C$5))) | E16: =IF(OR($C16="",$D16=""),"",$C16+$D16/1440) | M16: =IF(OR($C16="",$E16="",$H16="",$K16="Cancelada"),"",IF(COUNTIFS($A$5:$A$504,$A16,$H$5:$H$504,$H16,$K$5:$K$504,"<>Cancelada",$C$5:$C$504,"<"&$E16,$E$5:$E$504,">"&$C16)>1,"Se solapa con otra actividad en esta sala",""))
C17: =IF($A17="","",IF($B17<>"",$B17,IF($A17=$A16,$E16,Configuración!$C$5))) | E17: =IF(OR($C17="",$D17=""),"",$C17+$D17/1440) | M17: =IF(OR($C17="",$E17="",$H17="",$K17="Cancelada"),"",IF(COUNTIFS($A$5:$A$504,$A17,$H$5:$H$504,$H17,$K$5:$K$504,"<>Cancelada",$C$5:$C$504,"<"&$E17,$E$5:$E$504,">"&$C17)>1,"Se solapa con otra actividad en esta sala",""))
C18: =IF($A18="","",IF($B18<>"",$B18,IF($A18=$A17,$E17,Configuración!$C$5))) | E18: =IF(OR($C18="",$D18=""),"",$C18+$D18/1440) | M18: =IF(OR($C18="",$E18="",$H18="",$K18="Cancelada"),"",IF(COUNTIFS($A$5:$A$504,$A18,$H$5:$H$504,$H18,$K$5:$K$504,"<>Cancelada",$C$5:$C$504,"<"&$E18,$E$5:$E$504,">"&$C18)>1,"Se solapa con otra actividad en esta sala",""))
C19: =IF($A19="","",IF($B19<>"",$B19,IF($A19=$A18,$E18,Configuración!$C$5))) | E19: =IF(OR($C19="",$D19=""),"",$C19+$D19/1440) | M19: =IF(OR($C19="",$E19="",$H19="",$K19="Cancelada"),"",IF(COUNTIFS($A$5:$A$504,$A19,$H$5:$H$504,$H19,$K$5:$K$504,"<>Cancelada",$C$5:$C$504,"<"&$E19,$E$5:$E$504,">"&$C19)>1,"Se solapa con otra actividad en esta sala",""))
... C504: =IF($A504="","",IF($B504<>"",$B504,IF($A504=$A503,$E503,Configuración!$C$5))) | E504: =IF(OR($C504="",$D504=""),"",$C504+$D504/1440) | M504: =IF(OR($C504="",$E504="",$H504="",$K504="Cancelada"),"",IF(COUNTIFS($A$5:$A$504,$A504,$H$5:$H$504,$H504,$K$5:$K$504,"<>Cancelada",$C$5:$C$504,"<"&$E504,$E$5:$E$504,">"&$C504)>1,"Se solapa con otra actividad en esta sala",""))

Sheet Cuadrícula
A1: Cuadrícula del día | G1: Se rellena sola desde la Escaleta
A4: Día | B4: =Configuración!$F$6 | D4: ="Cambia el día en la celda amarilla · franjas de "&Configuración!$C$7&" min (ajústalo en Configuración)"
L5: Cálculos auxiliares (no editar)
A6: Hora | B6: =IF(Configuración!$B$22="","",Configuración!$B$22) | C6: =IF(Configuración!$B$23="","",Configuración!$B$23) | D6: =IF(Configuración!$B$24="","",Configuración!$B$24) | E6: =IF(Configuración!$B$25="","",Configuración!$B$25) | F6: =IF(Configuración!$B$26="","",Configuración!$B$26) | G6: =IF(Configuración!$B$27="","",Configuración!$B$27) | H6: =IF(Configuración!$B$28="","",Configuración!$B$28) | I6: =IF(Configuración!$B$29="","",Configuración!$B$29) | L6: fila 1 | M6: fila 2 | N6: fila 3 | O6: fila 4 | P6: fila 5 | Q6: fila 6 | R6: fila 7 | S6: fila 8 | U6: comité 1 | V6: comité 2 | W6: comité 3 | X6: comité 4 | Y6: comité 5 | Z6: comité 6 | AA6: comité 7 | AB6: comité 8
A7: =Configuración!$C$5 | B7: =IF(L7=0,"",IF(L7<>L6,INDEX(Escaleta!$F$1:$F$504,L7),IF(L7<>L5,TEXT(INDEX(Escaleta!$C$1:$C$504,L7),"hh:mm")&"–"&TEXT(INDEX(Escaleta!$E$1:$E$504,L7),"hh:mm"),""))) | C7: =IF(M7=0,"",IF(M7<>M6,INDEX(Escaleta!$F$1:$F$504,M7),IF(M7<>M5,TEXT(INDEX(Escaleta!$C$1:$C$504,M7),"hh:mm")&"–"&TEXT(INDEX(Escaleta!$E$1:$E$504,M7),"hh:mm"),""))) | D7: =IF(N7=0,"",IF(N7<>N6,INDEX(Escaleta!$F$1:$F$504,N7),IF(N7<>N5,TEXT(INDEX(Escaleta!$C$1:$C$504,N7),"hh:mm")&"–"&TEXT(INDEX(Escaleta!$E$1:$E$504,N7),"hh:mm"),""))) | E7: =IF(O7=0,"",IF(O7<>O6,INDEX(Escaleta!$F$1:$F$504,O7),IF(O7<>O5,TEXT(INDEX(Escaleta!$C$1:$C$504,O7),"hh:mm")&"–"&TEXT(INDEX(Escaleta!$E$1:$E$504,O7),"hh:mm"),""))) | F7: =IF(P7=0,"",IF(P7<>P6,INDEX(Escaleta!$F$1:$F$504,P7),IF(P7<>P5,TEXT(INDEX(Escaleta!$C$1:$C$504,P7),"hh:mm")&"–"&TEXT(INDEX(Escaleta!$E$1:$E$504,P7),"hh:mm"),""))) | G7: =IF(Q7=0,"",IF(Q7<>Q6,INDEX(Escaleta!$F$1:$F$504,Q7),IF(Q7<>Q5,TEXT(INDEX(Escaleta!$C$1:$C$504,Q7),"hh:mm")&"–"&TEXT(INDEX(Escaleta!$E$1:$E$504,Q7),"hh:mm"),""))) | H7: =IF(R7=0,"",IF(R7<>R6,INDEX(Escaleta!$F$1:$F$504,R7),IF(R7<>R5,TEXT(INDEX(Escaleta!$C$1:$C$504,R7),"hh:mm")&"–"&TEXT(INDEX(Escaleta!$E$1:$E$504,R7),"hh:mm"),""))) | I7: =IF(S7=0,"",IF(S7<>S6,INDEX(Escaleta!$F$1:$F$504,S7),IF(S7<>S5,TEXT(INDEX(Escaleta!$C$1:$C$504,S7),"hh:mm")&"–"&TEXT(INDEX(Escaleta!$E$1:$E$504,S7),"hh:mm"),""))) | L7: =IF(OR($A7="",B$6=""),0,SUMPRODUCT(MAX((Escaleta!$A$5:$A$504=$B$4)*(Escaleta!$H$5:$H$504=B$6)*(Escaleta!$K$5:$K$504<>"Cancelada")*(Escaleta!$C$5:$C$504<$A7+Configuración!$C$7/1440)*(Escaleta!$E$5:$E$504>$A7)*ROW(Escaleta!$A$5:$A$504)))) | M7: =IF(OR($A7="",C$6=""),0,SUMPRODUCT(MAX((Escaleta!$A$5:$A$504=$B$4)*(Escaleta!$H$5:$H$504=C$6)*(Escaleta!$K$5:$K$504<>"Cancelada")*(Escaleta!$C$5:$C$504<$A7+Configuración!$C$7/1440)*(Escaleta!$E$5:$E$504>$A7)*ROW(Escaleta!$A$5:$A$504)))) | N7: =IF(OR($A7="",D$6=""),0,SUMPRODUCT(MAX((Escaleta!$A$5:$A$504=$B$4)*(Escaleta!$H$5:$H$504=D$6)*(Escaleta!$K$5:$K$504<>"Cancelada")*(Escaleta!$C$5:$C$504<$A7+Configuración!$C$7/1440)*(Escaleta!$E$5:$E$504>$A7)*ROW(Escaleta!$A$5:$A$504)))) | O7: =IF(OR($A7="",E$6=""),0,SUMPRODUCT(MAX((Escaleta!$A$5:$A$504=$B$4)*(Escaleta!$H$5:$H$504=E$6)*(Escaleta!$K$5:$K$504<>"Cancelada")*(Escaleta!$C$5:$C$504<$A7+Configuración!$C$7/1440)*(Escaleta!$E$5:$E$504>$A7)*ROW(Escaleta!$A$5:$A$504)))) | P7: =IF(OR($A7="",F$6=""),0,SUMPRODUCT(MAX((Escaleta!$A$5:$A$504=$B$4)*(Escaleta!$H$5:$H$504=F$6)*(Escaleta!$K$5:$K$504<>"Cancelada")*(Escaleta!$C$5:$C$504<$A7+Configuración!$C$7/1440)*(Escaleta!$E$5:$E$504>$A7)*ROW(Escaleta!$A$5:$A$504)))) | Q7: =IF(OR($A7="",G$6=""),0,SUMPRODUCT(MAX((Escaleta!$A$5:$A$504=$B$4)*(Escaleta!$H$5:$H$504=G$6)*(Escaleta!$K$5:$K$504<>"Cancelada")*(Escaleta!$C$5:$C$504<$A7+Configuración!$C$7/1440)*(Escaleta!$E$5:$E$504>$A7)*ROW(Escaleta!$A$5:$A$504)))) | R7: =IF(OR($A7="",H$6=""),0,SUMPRODUCT(MAX((Escaleta!$A$5:$A$504=$B$4)*(Escaleta!$H$5:$H$504=H$6)*(Escaleta!$K$5:$K$504<>"Cancelada")*(Escaleta!$C$5:$C$504<$A7+Configuración!$C$7/1440)*(Escaleta!$E$5:$E$504>$A7)*ROW(Escaleta!$A$5:$A$504)))) | S7: =IF(OR($A7="",I$6=""),0,SUMPRODUCT(MAX((Escaleta!$A$5:$A$504=$B$4)*(Escaleta!$H$5:$H$504=I$6)*(Escaleta!$K$5:$K$504<>"Cancelada")*(Escaleta!$C$5:$C$504<$A7+Configuración!$C$7/1440)*(Escaleta!$E$5:$E$504>$A7)*ROW(Escaleta!$A$5:$A$504)))) | U7: =IF(L7=0,"",INDEX(Escaleta!$I$1:$I$504,L7)) | V7: =IF(M7=0,"",INDEX(Escaleta!$I$1:$I$504,M7)) | W7: =IF(N7=0,"",INDEX(Escaleta!$I$1:$I$504,N7)) | X7: =IF(O7=0,"",INDEX(Escaleta!$I$1:$I$504,O7)) | Y7: =IF(P7=0,"",INDEX(Escaleta!$I$1:$I$504,P7)) | Z7: =IF(Q7=0,"",INDEX(Escaleta!$I$1:$I$504,Q7)) | AA7: =IF(R7=0,"",INDEX(Escaleta!$I$1:$I$504,R7)) | AB7: =IF(S7=0,"",INDEX(Escaleta!$I$1:$I$504,S7))
A8: =IF(A7="","",IF(A7+Configuración!$C$7/1440>Configuración!$C$6-0.0001,"",A7+Configuración!$C$7/1440)) | B8: =IF(L8=0,"",IF(L8<>L7,INDEX(Escaleta!$F$1:$F$504,L8),IF(L8<>L6,TEXT(INDEX(Escaleta!$C$1:$C$504,L8),"hh:mm")&"–"&TEXT(INDEX(Escaleta!$E$1:$E$504,L8),"hh:mm"),""))) | C8: =IF(M8=0,"",IF(M8<>M7,INDEX(Escaleta!$F$1:$F$504,M8),IF(M8<>M6,TEXT(INDEX(Escaleta!$C$1:$C$504,M8),"hh:mm")&"–"&TEXT(INDEX(Escaleta!$E$1:$E$504,M8),"hh:mm"),""))) | D8: =IF(N8=0,"",IF(N8<>N7,INDEX(Escaleta!$F$1:$F$504,N8),IF(N8<>N6,TEXT(INDEX(Escaleta!$C$1:$C$504,N8),"hh:mm")&"–"&TEXT(INDEX(Escaleta!$E$1:$E$504,N8),"hh:mm"),""))) | E8: =IF(O8=0,"",IF(O8<>O7,INDEX(Escaleta!$F$1:$F$504,O8),IF(O8<>O6,TEXT(INDEX(Escaleta!$C$1:$C$504,O8),"hh:mm")&"–"&TEXT(INDEX(Escaleta!$E$1:$E$504,O8),"hh:mm"),""))) | F8: =IF(P8=0,"",IF(P8<>P7,INDEX(Escaleta!$F$1:$F$504,P8),IF(P8<>P6,TEXT(INDEX(Escaleta!$C$1:$C$504,P8),"hh:mm")&"–"&TEXT(INDEX(Escaleta!$E$1:$E$504,P8),"hh:mm"),""))) | G8: =IF(Q8=0,"",IF(Q8<>Q7,INDEX(Escaleta!$F$1:$F$504,Q8),IF(Q8<>Q6,TEXT(INDEX(Escaleta!$C$1:$C$504,Q8),"hh:mm")&"–"&TEXT(INDEX(Escaleta!$E$1:$E$504,Q8),"hh:mm"),""))) | H8: =IF(R8=0,"",IF(R8<>R7,INDEX(Escaleta!$F$1:$F$504,R8),IF(R8<>R6,TEXT(INDEX(Escaleta!$C$1:$C$504,R8),"hh:mm")&"–"&TEXT(INDEX(Escaleta!$E$1:$E$504,R8),"hh:mm"),""))) | I8: =IF(S8=0,"",IF(S8<>S7,INDEX(Escaleta!$F$1:$F$504,S8),IF(S8<>S6,TEXT(INDEX(Escaleta!$C$1:$C$504,S8),"hh:mm")&"–"&TEXT(INDEX(Escaleta!$E$1:$E$504,S8),"hh:mm"),""))) | L8: =IF(OR($A8="",B$6=""),0,SUMPRODUCT(MAX((Escaleta!$A$5:$A$504=$B$4)*(Escaleta!$H$5:$H$504=B$6)*(Escaleta!$K$5:$K$504<>"Cancelada")*(Escaleta!$C$5:$C$504<$A8+Configuración!$C$7/1440)*(Escaleta!$E$5:$E$504>$A8)*ROW(Escaleta!$A$5:$A$504)))) | M8: =IF(OR($A8="",C$6=""),0,SUMPRODUCT(MAX((Escaleta!$A$5:$A$504=$B$4)*(Escaleta!$H$5:$H$504=C$6)*(Escaleta!$K$5:$K$504<>"Cancelada")*(Escaleta!$C$5:$C$504<$A8+Configuración!$C$7/1440)*(Escaleta!$E$5:$E$504>$A8)*ROW(Escaleta!$A$5:$A$504)))) | N8: =IF(OR($A8="",D$6=""),0,SUMPRODUCT(MAX((Escaleta!$A$5:$A$504=$B$4)*(Escaleta!$H$5:$H$504=D$6)*(Escaleta!$K$5:$K$504<>"Cancelada")*(Escaleta!$C$5:$C$504<$A8+Configuración!$C$7/1440)*(Escaleta!$E$5:$E$504>$A8)*ROW(Escaleta!$A$5:$A$504)))) | O8: =IF(OR($A8="",E$6=""),0,SUMPRODUCT(MAX((Escaleta!$A$5:$A$504=$B$4)*(Escaleta!$H$5:$H$504=E$6)*(Escaleta!$K$5:$K$504<>"Cancelada")*(Escaleta!$C$5:$C$504<$A8+Configuración!$C$7/1440)*(Escaleta!$E$5:$E$504>$A8)*ROW(Escaleta!$A$5:$A$504)))) | P8: =IF(OR($A8="",F$6=""),0,SUMPRODUCT(MAX((Escaleta!$A$5:$A$504=$B$4)*(Escaleta!$H$5:$H$504=F$6)*(Escaleta!$K$5:$K$504<>"Cancelada")*(Escaleta!$C$5:$C$504<$A8+Configuración!$C$7/1440)*(Escaleta!$E$5:$E$504>$A8)*ROW(Escaleta!$A$5:$A$504)))) | Q8: =IF(OR($A8="",G$6=""),0,SUMPRODUCT(MAX((Escaleta!$A$5:$A$504=$B$4)*(Escaleta!$H$5:$H$504=G$6)*(Escaleta!$K$5:$K$504<>"Cancelada")*(Escaleta!$C$5:$C$504<$A8+Configuración!$C$7/1440)*(Escaleta!$E$5:$E$504>$A8)*ROW(Escaleta!$A$5:$A$504)))) | R8: =IF(OR($A8="",H$6=""),0,SUMPRODUCT(MAX((Escaleta!$A$5:$A$504=$B$4)*(Escaleta!$H$5:$H$504=H$6)*(Escaleta!$K$5:$K$504<>"Cancelada")*(Escaleta!$C$5:$C$504<$A8+Configuración!$C$7/1440)*(Escaleta!$E$5:$E$504>$A8)*ROW(Escaleta!$A$5:$A$504)))) | S8: =IF(OR($A8="",I$6=""),0,SUMPRODUCT(MAX((Escaleta!$A$5:$A$504=$B$4)*(Escaleta!$H$5:$H$504=I$6)*(Escaleta!$K$5:$K$504<>"Cancelada")*(Escaleta!$C$5:$C$504<$A8+Configuración!$C$7/1440)*(Escaleta!$E$5:$E$504>$A8)*ROW(Escaleta!$A$5:$A$504)))) | U8: =IF(L8=0,"",INDEX(Escaleta!$I$1:$I$504,L8)) | V8: =IF(M8=0,"",INDEX(Escaleta!$I$1:$I$504,M8)) | W8: =IF(N8=0,"",INDEX(Escaleta!$I$1:$I$504,N8)) | X8: =IF(O8=0,"",INDEX(Escaleta!$I$1:$I$504,O8)) | Y8: =IF(P8=0,"",INDEX(Escaleta!$I$1:$I$504,P8)) | Z8: =IF(Q8=0,"",INDEX(Escaleta!$I$1:$I$504,Q8)) | AA8: =IF(R8=0,"",INDEX(Escaleta!$I$1:$I$504,R8)) | AB8: =IF(S8=0,"",INDEX(Escaleta!$I$1:$I$504,S8))
A9: =IF(A8="","",IF(A8+Configuración!$C$7/1440>Configuración!$C$6-0.0001,"",A8+Configuración!$C$7/1440)) | B9: =IF(L9=0,"",IF(L9<>L8,INDEX(Escaleta!$F$1:$F$504,L9),IF(L9<>L7,TEXT(INDEX(Escaleta!$C$1:$C$504,L9),"hh:mm")&"–"&TEXT(INDEX(Escaleta!$E$1:$E$504,L9),"hh:mm"),""))) | C9: =IF(M9=0,"",IF(M9<>M8,INDEX(Escaleta!$F$1:$F$504,M9),IF(M9<>M7,TEXT(INDEX(Escaleta!$C$1:$C$504,M9),"hh:mm")&"–"&TEXT(INDEX(Escaleta!$E$1:$E$504,M9),"hh:mm"),""))) | D9: =IF(N9=0,"",IF(N9<>N8,INDEX(Escaleta!$F$1:$F$504,N9),IF(N9<>N7,TEXT(INDEX(Escaleta!$C$1:$C$504,N9),"hh:mm")&"–"&TEXT(INDEX(Escaleta!$E$1:$E$504,N9),"hh:mm"),""))) | E9: =IF(O9=0,"",IF(O9<>O8,INDEX(Escaleta!$F$1:$F$504,O9),IF(O9<>O7,TEXT(INDEX(Escaleta!$C$1:$C$504,O9),"hh:mm")&"–"&TEXT(INDEX(Escaleta!$E$1:$E$504,O9),"hh:mm"),""))) | F9: =IF(P9=0,"",IF(P9<>P8,INDEX(Escaleta!$F$1:$F$504,P9),IF(P9<>P7,TEXT(INDEX(Escaleta!$C$1:$C$504,P9),"hh:mm")&"–"&TEXT(INDEX(Escaleta!$E$1:$E$504,P9),"hh:mm"),""))) | G9: =IF(Q9=0,"",IF(Q9<>Q8,INDEX(Escaleta!$F$1:$F$504,Q9),IF(Q9<>Q7,TEXT(INDEX(Escaleta!$C$1:$C$504,Q9),"hh:mm")&"–"&TEXT(INDEX(Escaleta!$E$1:$E$504,Q9),"hh:mm"),""))) | H9: =IF(R9=0,"",IF(R9<>R8,INDEX(Escaleta!$F$1:$F$504,R9),IF(R9<>R7,TEXT(INDEX(Escaleta!$C$1:$C$504,R9),"hh:mm")&"–"&TEXT(INDEX(Escaleta!$E$1:$E$504,R9),"hh:mm"),""))) | I9: =IF(S9=0,"",IF(S9<>S8,INDEX(Escaleta!$F$1:$F$504,S9),IF(S9<>S7,TEXT(INDEX(Escaleta!$C$1:$C$504,S9),"hh:mm")&"–"&TEXT(INDEX(Escaleta!$E$1:$E$504,S9),"hh:mm"),""))) | L9: =IF(OR($A9="",B$6=""),0,SUMPRODUCT(MAX((Escaleta!$A$5:$A$504=$B$4)*(Escaleta!$H$5:$H$504=B$6)*(Escaleta!$K$5:$K$504<>"Cancelada")*(Escaleta!$C$5:$C$504<$A9+Configuración!$C$7/1440)*(Escaleta!$E$5:$E$504>$A9)*ROW(Escaleta!$A$5:$A$504)))) | M9: =IF(OR($A9="",C$6=""),0,SUMPRODUCT(MAX((Escaleta!$A$5:$A$504=$B$4)*(Escaleta!$H$5:$H$504=C$6)*(Escaleta!$K$5:$K$504<>"Cancelada")*(Escaleta!$C$5:$C$504<$A9+Configuración!$C$7/1440)*(Escaleta!$E$5:$E$504>$A9)*ROW(Escaleta!$A$5:$A$504)))) | N9: =IF(OR($A9="",D$6=""),0,SUMPRODUCT(MAX((Escaleta!$A$5:$A$504=$B$4)*(Escaleta!$H$5:$H$504=D$6)*(Escaleta!$K$5:$K$504<>"Cancelada")*(Escaleta!$C$5:$C$504<$A9+Configuración!$C$7/1440)*(Escaleta!$E$5:$E$504>$A9)*ROW(Escaleta!$A$5:$A$504)))) | O9: =IF(OR($A9="",E$6=""),0,SUMPRODUCT(MAX((Escaleta!$A$5:$A$504=$B$4)*(Escaleta!$H$5:$H$504=E$6)*(Escaleta!$K$5:$K$504<>"Cancelada")*(Escaleta!$C$5:$C$504<$A9+Configuración!$C$7/1440)*(Escaleta!$E$5:$E$504>$A9)*ROW(Escaleta!$A$5:$A$504)))) | P9: =IF(OR($A9="",F$6=""),0,SUMPRODUCT(MAX((Escaleta!$A$5:$A$504=$B$4)*(Escaleta!$H$5:$H$504=F$6)*(Escaleta!$K$5:$K$504<>"Cancelada")*(Escaleta!$C$5:$C$504<$A9+Configuración!$C$7/1440)*(Escaleta!$E$5:$E$504>$A9)*ROW(Escaleta!$A$5:$A$504)))) | Q9: =IF(OR($A9="",G$6=""),0,SUMPRODUCT(MAX((Escaleta!$A$5:$A$504=$B$4)*(Escaleta!$H$5:$H$504=G$6)*(Escaleta!$K$5:$K$504<>"Cancelada")*(Escaleta!$C$5:$C$504<$A9+Configuración!$C$7/1440)*(Escaleta!$E$5:$E$504>$A9)*ROW(Escaleta!$A$5:$A$504)))) | R9: =IF(OR($A9="",H$6=""),0,SUMPRODUCT(MAX((Escaleta!$A$5:$A$504=$B$4)*(Escaleta!$H$5:$H$504=H$6)*(Escaleta!$K$5:$K$504<>"Cancelada")*(Escaleta!$C$5:$C$504<$A9+Configuración!$C$7/1440)*(Escaleta!$E$5:$E$504>$A9)*ROW(Escaleta!$A$5:$A$504)))) | S9: =IF(OR($A9="",I$6=""),0,SUMPRODUCT(MAX((Escaleta!$A$5:$A$504=$B$4)*(Escaleta!$H$5:$H$504=I$6)*(Escaleta!$K$5:$K$504<>"Cancelada")*(Escaleta!$C$5:$C$504<$A9+Configuración!$C$7/1440)*(Escaleta!$E$5:$E$504>$A9)*ROW(Escaleta!$A$5:$A$504)))) | U9: =IF(L9=0,"",INDEX(Escaleta!$I$1:$I$504,L9)) | V9: =IF(M9=0,"",INDEX(Escaleta!$I$1:$I$504,M9)) | W9: =IF(N9=0,"",INDEX(Escaleta!$I$1:$I$504,N9)) | X9: =IF(O9=0,"",INDEX(Escaleta!$I$1:$I$504,O9)) | Y9: =IF(P9=0,"",INDEX(Escaleta!$I$1:$I$504,P9)) | Z9: =IF(Q9=0,"",INDEX(Escaleta!$I$1:$I$504,Q9)) | AA9: =IF(R9=0,"",INDEX(Escaleta!$I$1:$I$504,R9)) | AB9: =IF(S9=0,"",INDEX(Escaleta!$I$1:$I$504,S9))
A10: =IF(A9="","",IF(A9+Configuración!$C$7/1440>Configuración!$C$6-0.0001,"",A9+Configuración!$C$7/1440)) | B10: =IF(L10=0,"",IF(L10<>L9,INDEX(Escaleta!$F$1:$F$504,L10),IF(L10<>L8,TEXT(INDEX(Escaleta!$C$1:$C$504,L10),"hh:mm")&"–"&TEXT(INDEX(Escaleta!$E$1:$E$504,L10),"hh:mm"),""))) | C10: =IF(M10=0,"",IF(M10<>M9,INDEX(Escaleta!$F$1:$F$504,M10),IF(M10<>M8,TEXT(INDEX(Escaleta!$C$1:$C$504,M10),"hh:mm")&"–"&TEXT(INDEX(Escaleta!$E$1:$E$504,M10),"hh:mm"),""))) | D10: =IF(N10=0,"",IF(N10<>N9,INDEX(Escaleta!$F$1:$F$504,N10),IF(N10<>N8,TEXT(INDEX(Escaleta!$C$1:$C$504,N10),"hh:mm")&"–"&TEXT(INDEX(Escaleta!$E$1:$E$504,N10),"hh:mm"),""))) | E10: =IF(O10=0,"",IF(O10<>O9,INDEX(Escaleta!$F$1:$F$504,O10),IF(O10<>O8,TEXT(INDEX(Escaleta!$C$1:$C$504,O10),"hh:mm")&"–"&TEXT(INDEX(Escaleta!$E$1:$E$504,O10),"hh:mm"),""))) | F10: =IF(P10=0,"",IF(P10<>P9,INDEX(Escaleta!$F$1:$F$504,P10),IF(P10<>P8,TEXT(INDEX(Escaleta!$C$1:$C$504,P10),"hh:mm")&"–"&TEXT(INDEX(Escaleta!$E$1:$E$504,P10),"hh:mm"),""))) | G10: =IF(Q10=0,"",IF(Q10<>Q9,INDEX(Escaleta!$F$1:$F$504,Q10),IF(Q10<>Q8,TEXT(INDEX(Escaleta!$C$1:$C$504,Q10),"hh:mm")&"–"&TEXT(INDEX(Escaleta!$E$1:$E$504,Q10),"hh:mm"),""))) | H10: =IF(R10=0,"",IF(R10<>R9,INDEX(Escaleta!$F$1:$F$504,R10),IF(R10<>R8,TEXT(INDEX(Escaleta!$C$1:$C$504,R10),"hh:mm")&"–"&TEXT(INDEX(Escaleta!$E$1:$E$504,R10),"hh:mm"),""))) | I10: =IF(S10=0,"",IF(S10<>S9,INDEX(Escaleta!$F$1:$F$504,S10),IF(S10<>S8,TEXT(INDEX(Escaleta!$C$1:$C$504,S10),"hh:mm")&"–"&TEXT(INDEX(Escaleta!$E$1:$E$504,S10),"hh:mm"),""))) | L10: =IF(OR($A10="",B$6=""),0,SUMPRODUCT(MAX((Escaleta!$A$5:$A$504=$B$4)*(Escaleta!$H$5:$H$504=B$6)*(Escaleta!$K$5:$K$504<>"Cancelada")*(Escaleta!$C$5:$C$504<$A10+Configuración!$C$7/1440)*(Escaleta!$E$5:$E$504>$A10)*ROW(Escaleta!$A$5:$A$504)))) | M10: =IF(OR($A10="",C$6=""),0,SUMPRODUCT(MAX((Escaleta!$A$5:$A$504=$B$4)*(Escaleta!$H$5:$H$504=C$6)*(Escaleta!$K$5:$K$504<>"Cancelada")*(Escaleta!$C$5:$C$504<$A10+Configuración!$C$7/1440)*(Escaleta!$E$5:$E$504>$A10)*ROW(Escaleta!$A$5:$A$504)))) | N10: =IF(OR($A10="",D$6=""),0,SUMPRODUCT(MAX((Escaleta!$A$5:$A$504=$B$4)*(Escaleta!$H$5:$H$504=D$6)*(Escaleta!$K$5:$K$504<>"Cancelada")*(Escaleta!$C$5:$C$504<$A10+Configuración!$C$7/1440)*(Escaleta!$E$5:$E$504>$A10)*ROW(Escaleta!$A$5:$A$504)))) | O10: =IF(OR($A10="",E$6=""),0,SUMPRODUCT(MAX((Escaleta!$A$5:$A$504=$B$4)*(Escaleta!$H$5:$H$504=E$6)*(Escaleta!$K$5:$K$504<>"Cancelada")*(Escaleta!$C$5:$C$504<$A10+Configuración!$C$7/1440)*(Escaleta!$E$5:$E$504>$A10)*ROW(Escaleta!$A$5:$A$504)))) | P10: =IF(OR($A10="",F$6=""),0,SUMPRODUCT(MAX((Escaleta!$A$5:$A$504=$B$4)*(Escaleta!$H$5:$H$504=F$6)*(Escaleta!$K$5:$K$504<>"Cancelada")*(Escaleta!$C$5:$C$504<$A10+Configuración!$C$7/1440)*(Escaleta!$E$5:$E$504>$A10)*ROW(Escaleta!$A$5:$A$504)))) | Q10: =IF(OR($A10="",G$6=""),0,SUMPRODUCT(MAX((Escaleta!$A$5:$A$504=$B$4)*(Escaleta!$H$5:$H$504=G$6)*(Escaleta!$K$5:$K$504<>"Cancelada")*(Escaleta!$C$5:$C$504<$A10+Configuración!$C$7/1440)*(Escaleta!$E$5:$E$504>$A10)*ROW(Escaleta!$A$5:$A$504)))) | R10: =IF(OR($A10="",H$6=""),0,SUMPRODUCT(MAX((Escaleta!$A$5:$A$504=$B$4)*(Escaleta!$H$5:$H$504=H$6)*(Escaleta!$K$5:$K$504<>"Cancelada")*(Escaleta!$C$5:$C$504<$A10+Configuración!$C$7/1440)*(Escaleta!$E$5:$E$504>$A10)*ROW(Escaleta!$A$5:$A$504)))) | S10: =IF(OR($A10="",I$6=""),0,SUMPRODUCT(MAX((Escaleta!$A$5:$A$504=$B$4)*(Escaleta!$H$5:$H$504=I$6)*(Escaleta!$K$5:$K$504<>"Cancelada")*(Escaleta!$C$5:$C$504<$A10+Configuración!$C$7/1440)*(Escaleta!$E$5:$E$504>$A10)*ROW(Escaleta!$A$5:$A$504)))) | U10: =IF(L10=0,"",INDEX(Escaleta!$I$1:$I$504,L10)) | V10: =IF(M10=0,"",INDEX(Escaleta!$I$1:$I$504,M10)) | W10: =IF(N10=0,"",INDEX(Escaleta!$I$1:$I$504,N10)) | X10: =IF(O10=0,"",INDEX(Escaleta!$I$1:$I$504,O10)) | Y10: =IF(P10=0,"",INDEX(Escaleta!$I$1:$I$504,P10)) | Z10: =IF(Q10=0,"",INDEX(Escaleta!$I$1:$I$504,Q10)) | AA10: =IF(R10=0,"",INDEX(Escaleta!$I$1:$I$504,R10)) | AB10: =IF(S10=0,"",INDEX(Escaleta!$I$1:$I$504,S10))
A11: =IF(A10="","",IF(A10+Configuración!$C$7/1440>Configuración!$C$6-0.0001,"",A10+Configuración!$C$7/1440)) | B11: =IF(L11=0,"",IF(L11<>L10,INDEX(Escaleta!$F$1:$F$504,L11),IF(L11<>L9,TEXT(INDEX(Escaleta!$C$1:$C$504,L11),"hh:mm")&"–"&TEXT(INDEX(Escaleta!$E$1:$E$504,L11),"hh:mm"),""))) | C11: =IF(M11=0,"",IF(M11<>M10,INDEX(Escaleta!$F$1:$F$504,M11),IF(M11<>M9,TEXT(INDEX(Escaleta!$C$1:$C$504,M11),"hh:mm")&"–"&TEXT(INDEX(Escaleta!$E$1:$E$504,M11),"hh:mm"),""))) | D11: =IF(N11=0,"",IF(N11<>N10,INDEX(Escaleta!$F$1:$F$504,N11),IF(N11<>N9,TEXT(INDEX(Escaleta!$C$1:$C$504,N11),"hh:mm")&"–"&TEXT(INDEX(Escaleta!$E$1:$E$504,N11),"hh:mm"),""))) | E11: =IF(O11=0,"",IF(O11<>O10,INDEX(Escaleta!$F$1:$F$504,O11),IF(O11<>O9,TEXT(INDEX(Escaleta!$C$1:$C$504,O11),"hh:mm")&"–"&TEXT(INDEX(Escaleta!$E$1:$E$504,O11),"hh:mm"),""))) | F11: =IF(P11=0,"",IF(P11<>P10,INDEX(Escaleta!$F$1:$F$504,P11),IF(P11<>P9,TEXT(INDEX(Escaleta!$C$1:$C$504,P11),"hh:mm")&"–"&TEXT(INDEX(Escaleta!$E$1:$E$504,P11),"hh:mm"),""))) | G11: =IF(Q11=0,"",IF(Q11<>Q10,INDEX(Escaleta!$F$1:$F$504,Q11),IF(Q11<>Q9,TEXT(INDEX(Escaleta!$C$1:$C$504,Q11),"hh:mm")&"–"&TEXT(INDEX(Escaleta!$E$1:$E$504,Q11),"hh:mm"),""))) | H11: =IF(R11=0,"",IF(R11<>R10,INDEX(Escaleta!$F$1:$F$504,R11),IF(R11<>R9,TEXT(INDEX(Escaleta!$C$1:$C$504,R11),"hh:mm")&"–"&TEXT(INDEX(Escaleta!$E$1:$E$504,R11),"hh:mm"),""))) | I11: =IF(S11=0,"",IF(S11<>S10,INDEX(Escaleta!$F$1:$F$504,S11),IF(S11<>S9,TEXT(INDEX(Escaleta!$C$1:$C$504,S11),"hh:mm")&"–"&TEXT(INDEX(Escaleta!$E$1:$E$504,S11),"hh:mm"),""))) | L11: =IF(OR($A11="",B$6=""),0,SUMPRODUCT(MAX((Escaleta!$A$5:$A$504=$B$4)*(Escaleta!$H$5:$H$504=B$6)*(Escaleta!$K$5:$K$504<>"Cancelada")*(Escaleta!$C$5:$C$504<$A11+Configuración!$C$7/1440)*(Escaleta!$E$5:$E$504>$A11)*ROW(Escaleta!$A$5:$A$504)))) | M11: =IF(OR($A11="",C$6=""),0,SUMPRODUCT(MAX((Escaleta!$A$5:$A$504=$B$4)*(Escaleta!$H$5:$H$504=C$6)*(Escaleta!$K$5:$K$504<>"Cancelada")*(Escaleta!$C$5:$C$504<$A11+Configuración!$C$7/1440)*(Escaleta!$E$5:$E$504>$A11)*ROW(Escaleta!$A$5:$A$504)))) | N11: =IF(OR($A11="",D$6=""),0,SUMPRODUCT(MAX((Escaleta!$A$5:$A$504=$B$4)*(Escaleta!$H$5:$H$504=D$6)*(Escaleta!$K$5:$K$504<>"Cancelada")*(Escaleta!$C$5:$C$504<$A11+Configuración!$C$7/1440)*(Escaleta!$E$5:$E$504>$A11)*ROW(Escaleta!$A$5:$A$504)))) | O11: =IF(OR($A11="",E$6=""),0,SUMPRODUCT(MAX((Escaleta!$A$5:$A$504=$B$4)*(Escaleta!$H$5:$H$504=E$6)*(Escaleta!$K$5:$K$504<>"Cancelada")*(Escaleta!$C$5:$C$504<$A11+Configuración!$C$7/1440)*(Escaleta!$E$5:$E$504>$A11)*ROW(Escaleta!$A$5:$A$504)))) | P11: =IF(OR($A11="",F$6=""),0,SUMPRODUCT(MAX((Escaleta!$A$5:$A$504=$B$4)*(Escaleta!$H$5:$H$504=F$6)*(Escaleta!$K$5:$K$504<>"Cancelada")*(Escaleta!$C$5:$C$504<$A11+Configuración!$C$7/1440)*(Escaleta!$E$5:$E$504>$A11)*ROW(Escaleta!$A$5:$A$504)))) | Q11: =IF(OR($A11="",G$6=""),0,SUMPRODUCT(MAX((Escaleta!$A$5:$A$504=$B$4)*(Escaleta!$H$5:$H$504=G$6)*(Escaleta!$K$5:$K$504<>"Cancelada")*(Escaleta!$C$5:$C$504<$A11+Configuración!$C$7/1440)*(Escaleta!$E$5:$E$504>$A11)*ROW(Escaleta!$A$5:$A$504)))) | R11: =IF(OR($A11="",H$6=""),0,SUMPRODUCT(MAX((Escaleta!$A$5:$A$504=$B$4)*(Escaleta!$H$5:$H$504=H$6)*(Escaleta!$K$5:$K$504<>"Cancelada")*(Escaleta!$C$5:$C$504<$A11+Configuración!$C$7/1440)*(Escaleta!$E$5:$E$504>$A11)*ROW(Escaleta!$A$5:$A$504)))) | S11: =IF(OR($A11="",I$6=""),0,SUMPRODUCT(MAX((Escaleta!$A$5:$A$504=$B$4)*(Escaleta!$H$5:$H$504=I$6)*(Escaleta!$K$5:$K$504<>"Cancelada")*(Escaleta!$C$5:$C$504<$A11+Configuración!$C$7/1440)*(Escaleta!$E$5:$E$504>$A11)*ROW(Escaleta!$A$5:$A$504)))) | U11: =IF(L11=0,"",INDEX(Escaleta!$I$1:$I$504,L11)) | V11: =IF(M11=0,"",INDEX(Escaleta!$I$1:$I$504,M11)) | W11: =IF(N11=0,"",INDEX(Escaleta!$I$1:$I$504,N11)) | X11: =IF(O11=0,"",INDEX(Escaleta!$I$1:$I$504,O11)) | Y11: =IF(P11=0,"",INDEX(Escaleta!$I$1:$I$504,P11)) | Z11: =IF(Q11=0,"",INDEX(Escaleta!$I$1:$I$504,Q11)) | AA11: =IF(R11=0,"",INDEX(Escaleta!$I$1:$I$504,R11)) | AB11: =IF(S11=0,"",INDEX(Escaleta!$I$1:$I$504,S11))
A12: =IF(A11="","",IF(A11+Configuración!$C$7/1440>Configuración!$C$6-0.0001,"",A11+Configuración!$C$7/1440)) | B12: =IF(L12=0,"",IF(L12<>L11,INDEX(Escaleta!$F$1:$F$504,L12),IF(L12<>L10,TEXT(INDEX(Escaleta!$C$1:$C$504,L12),"hh:mm")&"–"&TEXT(INDEX(Escaleta!$E$1:$E$504,L12),"hh:mm"),""))) | C12: =IF(M12=0,"",IF(M12<>M11,INDEX(Escaleta!$F$1:$F$504,M12),IF(M12<>M10,TEXT(INDEX(Escaleta!$C$1:$C$504,M12),"hh:mm")&"–"&TEXT(INDEX(Escaleta!$E$1:$E$504,M12),"hh:mm"),""))) | D12: =IF(N12=0,"",IF(N12<>N11,INDEX(Escaleta!$F$1:$F$504,N12),IF(N12<>N10,TEXT(INDEX(Escaleta!$C$1:$C$504,N12),"hh:mm")&"–"&TEXT(INDEX(Escaleta!$E$1:$E$504,N12),"hh:mm"),""))) | E12: =IF(O12=0,"",IF(O12<>O11,INDEX(Escaleta!$F$1:$F$504,O12),IF(O12<>O10,TEXT(INDEX(Escaleta!$C$1:$C$504,O12),"hh:mm")&"–"&TEXT(INDEX(Escaleta!$E$1:$E$504,O12),"hh:mm"),""))) | F12: =IF(P12=0,"",IF(P12<>P11,INDEX(Escaleta!$F$1:$F$504,P12),IF(P12<>P10,TEXT(INDEX(Escaleta!$C$1:$C$504,P12),"hh:mm")&"–"&TEXT(INDEX(Escaleta!$E$1:$E$504,P12),"hh:mm"),""))) | G12: =IF(Q12=0,"",IF(Q12<>Q11,INDEX(Escaleta!$F$1:$F$504,Q12),IF(Q12<>Q10,TEXT(INDEX(Escaleta!$C$1:$C$504,Q12),"hh:mm")&"–"&TEXT(INDEX(Escaleta!$E$1:$E$504,Q12),"hh:mm"),""))) | H12: =IF(R12=0,"",IF(R12<>R11,INDEX(Escaleta!$F$1:$F$504,R12),IF(R12<>R10,TEXT(INDEX(Escaleta!$C$1:$C$504,R12),"hh:mm")&"–"&TEXT(INDEX(Escaleta!$E$1:$E$504,R12),"hh:mm"),""))) | I12: =IF(S12=0,"",IF(S12<>S11,INDEX(Escaleta!$F$1:$F$504,S12),IF(S12<>S10,TEXT(INDEX(Escaleta!$C$1:$C$504,S12),"hh:mm")&"–"&TEXT(INDEX(Escaleta!$E$1:$E$504,S12),"hh:mm"),""))) | L12: =IF(OR($A12="",B$6=""),0,SUMPRODUCT(MAX((Escaleta!$A$5:$A$504=$B$4)*(Escaleta!$H$5:$H$504=B$6)*(Escaleta!$K$5:$K$504<>"Cancelada")*(Escaleta!$C$5:$C$504<$A12+Configuración!$C$7/1440)*(Escaleta!$E$5:$E$504>$A12)*ROW(Escaleta!$A$5:$A$504)))) | M12: =IF(OR($A12="",C$6=""),0,SUMPRODUCT(MAX((Escaleta!$A$5:$A$504=$B$4)*(Escaleta!$H$5:$H$504=C$6)*(Escaleta!$K$5:$K$504<>"Cancelada")*(Escaleta!$C$5:$C$504<$A12+Configuración!$C$7/1440)*(Escaleta!$E$5:$E$504>$A12)*ROW(Escaleta!$A$5:$A$504)))) | N12: =IF(OR($A12="",D$6=""),0,SUMPRODUCT(MAX((Escaleta!$A$5:$A$504=$B$4)*(Escaleta!$H$5:$H$504=D$6)*(Escaleta!$K$5:$K$504<>"Cancelada")*(Escaleta!$C$5:$C$504<$A12+Configuración!$C$7/1440)*(Escaleta!$E$5:$E$504>$A12)*ROW(Escaleta!$A$5:$A$504)))) | O12: =IF(OR($A12="",E$6=""),0,SUMPRODUCT(MAX((Escaleta!$A$5:$A$504=$B$4)*(Escaleta!$H$5:$H$504=E$6)*(Escaleta!$K$5:$K$504<>"Cancelada")*(Escaleta!$C$5:$C$504<$A12+Configuración!$C$7/1440)*(Escaleta!$E$5:$E$504>$A12)*ROW(Escaleta!$A$5:$A$504)))) | P12: =IF(OR($A12="",F$6=""),0,SUMPRODUCT(MAX((Escaleta!$A$5:$A$504=$B$4)*(Escaleta!$H$5:$H$504=F$6)*(Escaleta!$K$5:$K$504<>"Cancelada")*(Escaleta!$C$5:$C$504<$A12+Configuración!$C$7/1440)*(Escaleta!$E$5:$E$504>$A12)*ROW(Escaleta!$A$5:$A$504)))) | Q12: =IF(OR($A12="",G$6=""),0,SUMPRODUCT(MAX((Escaleta!$A$5:$A$504=$B$4)*(Escaleta!$H$5:$H$504=G$6)*(Escaleta!$K$5:$K$504<>"Cancelada")*(Escaleta!$C$5:$C$504<$A12+Configuración!$C$7/1440)*(Escaleta!$E$5:$E$504>$A12)*ROW(Escaleta!$A$5:$A$504)))) | R12: =IF(OR($A12="",H$6=""),0,SUMPRODUCT(MAX((Escaleta!$A$5:$A$504=$B$4)*(Escaleta!$H$5:$H$504=H$6)*(Escaleta!$K$5:$K$504<>"Cancelada")*(Escaleta!$C$5:$C$504<$A12+Configuración!$C$7/1440)*(Escaleta!$E$5:$E$504>$A12)*ROW(Escaleta!$A$5:$A$504)))) | S12: =IF(OR($A12="",I$6=""),0,SUMPRODUCT(MAX((Escaleta!$A$5:$A$504=$B$4)*(Escaleta!$H$5:$H$504=I$6)*(Escaleta!$K$5:$K$504<>"Cancelada")*(Escaleta!$C$5:$C$504<$A12+Configuración!$C$7/1440)*(Escaleta!$E$5:$E$504>$A12)*ROW(Escaleta!$A$5:$A$504)))) | U12: =IF(L12=0,"",INDEX(Escaleta!$I$1:$I$504,L12)) | V12: =IF(M12=0,"",INDEX(Escaleta!$I$1:$I$504,M12)) | W12: =IF(N12=0,"",INDEX(Escaleta!$I$1:$I$504,N12)) | X12: =IF(O12=0,"",INDEX(Escaleta!$I$1:$I$504,O12)) | Y12: =IF(P12=0,"",INDEX(Escaleta!$I$1:$I$504,P12)) | Z12: =IF(Q12=0,"",INDEX(Escaleta!$I$1:$I$504,Q12)) | AA12: =IF(R12=0,"",INDEX(Escaleta!$I$1:$I$504,R12)) | AB12: =IF(S12=0,"",INDEX(Escaleta!$I$1:$I$504,S12))
A13: =IF(A12="","",IF(A12+Configuración!$C$7/1440>Configuración!$C$6-0.0001,"",A12+Configuración!$C$7/1440)) | B13: =IF(L13=0,"",IF(L13<>L12,INDEX(Escaleta!$F$1:$F$504,L13),IF(L13<>L11,TEXT(INDEX(Escaleta!$C$1:$C$504,L13),"hh:mm")&"–"&TEXT(INDEX(Escaleta!$E$1:$E$504,L13),"hh:mm"),""))) | C13: =IF(M13=0,"",IF(M13<>M12,INDEX(Escaleta!$F$1:$F$504,M13),IF(M13<>M11,TEXT(INDEX(Escaleta!$C$1:$C$504,M13),"hh:mm")&"–"&TEXT(INDEX(Escaleta!$E$1:$E$504,M13),"hh:mm"),""))) | D13: =IF(N13=0,"",IF(N13<>N12,INDEX(Escaleta!$F$1:$F$504,N13),IF(N13<>N11,TEXT(INDEX(Escaleta!$C$1:$C$504,N13),"hh:mm")&"–"&TEXT(INDEX(Escaleta!$E$1:$E$504,N13),"hh:mm"),""))) | E13: =IF(O13=0,"",IF(O13<>O12,INDEX(Escaleta!$F$1:$F$504,O13),IF(O13<>O11,TEXT(INDEX(Escaleta!$C$1:$C$504,O13),"hh:mm")&"–"&TEXT(INDEX(Escaleta!$E$1:$E$504,O13),"hh:mm"),""))) | F13: =IF(P13=0,"",IF(P13<>P12,INDEX(Escaleta!$F$1:$F$504,P13),IF(P13<>P11,TEXT(INDEX(Escaleta!$C$1:$C$504,P13),"hh:mm")&"–"&TEXT(INDEX(Escaleta!$E$1:$E$504,P13),"hh:mm"),""))) | G13: =IF(Q13=0,"",IF(Q13<>Q12,INDEX(Escaleta!$F$1:$F$504,Q13),IF(Q13<>Q11,TEXT(INDEX(Escaleta!$C$1:$C$504,Q13),"hh:mm")&"–"&TEXT(INDEX(Escaleta!$E$1:$E$504,Q13),"hh:mm"),""))) | H13: =IF(R13=0,"",IF(R13<>R12,INDEX(Escaleta!$F$1:$F$504,R13),IF(R13<>R11,TEXT(INDEX(Escaleta!$C$1:$C$504,R13),"hh:mm")&"–"&TEXT(INDEX(Escaleta!$E$1:$E$504,R13),"hh:mm"),""))) | I13: =IF(S13=0,"",IF(S13<>S12,INDEX(Escaleta!$F$1:$F$504,S13),IF(S13<>S11,TEXT(INDEX(Escaleta!$C$1:$C$504,S13),"hh:mm")&"–"&TEXT(INDEX(Escaleta!$E$1:$E$504,S13),"hh:mm"),""))) | L13: =IF(OR($A13="",B$6=""),0,SUMPRODUCT(MAX((Escaleta!$A$5:$A$504=$B$4)*(Escaleta!$H$5:$H$504=B$6)*(Escaleta!$K$5:$K$504<>"Cancelada")*(Escaleta!$C$5:$C$504<$A13+Configuración!$C$7/1440)*(Escaleta!$E$5:$E$504>$A13)*ROW(Escaleta!$A$5:$A$504)))) | M13: =IF(OR($A13="",C$6=""),0,SUMPRODUCT(MAX((Escaleta!$A$5:$A$504=$B$4)*(Escaleta!$H$5:$H$504=C$6)*(Escaleta!$K$5:$K$504<>"Cancelada")*(Escaleta!$C$5:$C$504<$A13+Configuración!$C$7/1440)*(Escaleta!$E$5:$E$504>$A13)*ROW(Escaleta!$A$5:$A$504)))) | N13: =IF(OR($A13="",D$6=""),0,SUMPRODUCT(MAX((Escaleta!$A$5:$A$504=$B$4)*(Escaleta!$H$5:$H$504=D$6)*(Escaleta!$K$5:$K$504<>"Cancelada")*(Escaleta!$C$5:$C$504<$A13+Configuración!$C$7/1440)*(Escaleta!$E$5:$E$504>$A13)*ROW(Escaleta!$A$5:$A$504)))) | O13: =IF(OR($A13="",E$6=""),0,SUMPRODUCT(MAX((Escaleta!$A$5:$A$504=$B$4)*(Escaleta!$H$5:$H$504=E$6)*(Escaleta!$K$5:$K$504<>"Cancelada")*(Escaleta!$C$5:$C$504<$A13+Configuración!$C$7/1440)*(Escaleta!$E$5:$E$504>$A13)*ROW(Escaleta!$A$5:$A$504)))) | P13: =IF(OR($A13="",F$6=""),0,SUMPRODUCT(MAX((Escaleta!$A$5:$A$504=$B$4)*(Escaleta!$H$5:$H$504=F$6)*(Escaleta!$K$5:$K$504<>"Cancelada")*(Escaleta!$C$5:$C$504<$A13+Configuración!$C$7/1440)*(Escaleta!$E$5:$E$504>$A13)*ROW(Escaleta!$A$5:$A$504)))) | Q13: =IF(OR($A13="",G$6=""),0,SUMPRODUCT(MAX((Escaleta!$A$5:$A$504=$B$4)*(Escaleta!$H$5:$H$504=G$6)*(Escaleta!$K$5:$K$504<>"Cancelada")*(Escaleta!$C$5:$C$504<$A13+Configuración!$C$7/1440)*(Escaleta!$E$5:$E$504>$A13)*ROW(Escaleta!$A$5:$A$504)))) | R13: =IF(OR($A13="",H$6=""),0,SUMPRODUCT(MAX((Escaleta!$A$5:$A$504=$B$4)*(Escaleta!$H$5:$H$504=H$6)*(Escaleta!$K$5:$K$504<>"Cancelada")*(Escaleta!$C$5:$C$504<$A13+Configuración!$C$7/1440)*(Escaleta!$E$5:$E$504>$A13)*ROW(Escaleta!$A$5:$A$504)))) | S13: =IF(OR($A13="",I$6=""),0,SUMPRODUCT(MAX((Escaleta!$A$5:$A$504=$B$4)*(Escaleta!$H$5:$H$504=I$6)*(Escaleta!$K$5:$K$504<>"Cancelada")*(Escaleta!$C$5:$C$504<$A13+Configuración!$C$7/1440)*(Escaleta!$E$5:$E$504>$A13)*ROW(Escaleta!$A$5:$A$504)))) | U13: =IF(L13=0,"",INDEX(Escaleta!$I$1:$I$504,L13)) | V13: =IF(M13=0,"",INDEX(Escaleta!$I$1:$I$504,M13)) | W13: =IF(N13=0,"",INDEX(Escaleta!$I$1:$I$504,N13)) | X13: =IF(O13=0,"",INDEX(Escaleta!$I$1:$I$504,O13)) | Y13: =IF(P13=0,"",INDEX(Escaleta!$I$1:$I$504,P13)) | Z13: =IF(Q13=0,"",INDEX(Escaleta!$I$1:$I$504,Q13)) | AA13: =IF(R13=0,"",INDEX(Escaleta!$I$1:$I$504,R13)) | AB13: =IF(S13=0,"",INDEX(Escaleta!$I$1:$I$504,S13))
A14: =IF(A13="","",IF(A13+Configuración!$C$7/1440>Configuración!$C$6-0.0001,"",A13+Configuración!$C$7/1440)) | B14: =IF(L14=0,"",IF(L14<>L13,INDEX(Escaleta!$F$1:$F$504,L14),IF(L14<>L12,TEXT(INDEX(Escaleta!$C$1:$C$504,L14),"hh:mm")&"–"&TEXT(INDEX(Escaleta!$E$1:$E$504,L14),"hh:mm"),""))) | C14: =IF(M14=0,"",IF(M14<>M13,INDEX(Escaleta!$F$1:$F$504,M14),IF(M14<>M12,TEXT(INDEX(Escaleta!$C$1:$C$504,M14),"hh:mm")&"–"&TEXT(INDEX(Escaleta!$E$1:$E$504,M14),"hh:mm"),""))) | D14: =IF(N14=0,"",IF(N14<>N13,INDEX(Escaleta!$F$1:$F$504,N14),IF(N14<>N12,TEXT(INDEX(Escaleta!$C$1:$C$504,N14),"hh:mm")&"–"&TEXT(INDEX(Escaleta!$E$1:$E$504,N14),"hh:mm"),""))) | E14: =IF(O14=0,"",IF(O14<>O13,INDEX(Escaleta!$F$1:$F$504,O14),IF(O14<>O12,TEXT(INDEX(Escaleta!$C$1:$C$504,O14),"hh:mm")&"–"&TEXT(INDEX(Escaleta!$E$1:$E$504,O14),"hh:mm"),""))) | F14: =IF(P14=0,"",IF(P14<>P13,INDEX(Escaleta!$F$1:$F$504,P14),IF(P14<>P12,TEXT(INDEX(Escaleta!$C$1:$C$504,P14),"hh:mm")&"–"&TEXT(INDEX(Escaleta!$E$1:$E$504,P14),"hh:mm"),""))) | G14: =IF(Q14=0,"",IF(Q14<>Q13,INDEX(Escaleta!$F$1:$F$504,Q14),IF(Q14<>Q12,TEXT(INDEX(Escaleta!$C$1:$C$504,Q14),"hh:mm")&"–"&TEXT(INDEX(Escaleta!$E$1:$E$504,Q14),"hh:mm"),""))) | H14: =IF(R14=0,"",IF(R14<>R13,INDEX(Escaleta!$F$1:$F$504,R14),IF(R14<>R12,TEXT(INDEX(Escaleta!$C$1:$C$504,R14),"hh:mm")&"–"&TEXT(INDEX(Escaleta!$E$1:$E$504,R14),"hh:mm"),""))) | I14: =IF(S14=0,"",IF(S14<>S13,INDEX(Escaleta!$F$1:$F$504,S14),IF(S14<>S12,TEXT(INDEX(Escaleta!$C$1:$C$504,S14),"hh:mm")&"–"&TEXT(INDEX(Escaleta!$E$1:$E$504,S14),"hh:mm"),""))) | L14: =IF(OR($A14="",B$6=""),0,SUMPRODUCT(MAX((Escaleta!$A$5:$A$504=$B$4)*(Escaleta!$H$5:$H$504=B$6)*(Escaleta!$K$5:$K$504<>"Cancelada")*(Escaleta!$C$5:$C$504<$A14+Configuración!$C$7/1440)*(Escaleta!$E$5:$E$504>$A14)*ROW(Escaleta!$A$5:$A$504)))) | M14: =IF(OR($A14="",C$6=""),0,SUMPRODUCT(MAX((Escaleta!$A$5:$A$504=$B$4)*(Escaleta!$H$5:$H$504=C$6)*(Escaleta!$K$5:$K$504<>"Cancelada")*(Escaleta!$C$5:$C$504<$A14+Configuración!$C$7/1440)*(Escaleta!$E$5:$E$504>$A14)*ROW(Escaleta!$A$5:$A$504)))) | N14: =IF(OR($A14="",D$6=""),0,SUMPRODUCT(MAX((Escaleta!$A$5:$A$504=$B$4)*(Escaleta!$H$5:$H$504=D$6)*(Escaleta!$K$5:$K$504<>"Cancelada")*(Escaleta!$C$5:$C$504<$A14+Configuración!$C$7/1440)*(Escaleta!$E$5:$E$504>$A14)*ROW(Escaleta!$A$5:$A$504)))) | O14: =IF(OR($A14="",E$6=""),0,SUMPRODUCT(MAX((Escaleta!$A$5:$A$504=$B$4)*(Escaleta!$H$5:$H$504=E$6)*(Escaleta!$K$5:$K$504<>"Cancelada")*(Escaleta!$C$5:$C$504<$A14+Configuración!$C$7/1440)*(Escaleta!$E$5:$E$504>$A14)*ROW(Escaleta!$A$5:$A$504)))) | P14: =IF(OR($A14="",F$6=""),0,SUMPRODUCT(MAX((Escaleta!$A$5:$A$504=$B$4)*(Escaleta!$H$5:$H$504=F$6)*(Escaleta!$K$5:$K$504<>"Cancelada")*(Escaleta!$C$5:$C$504<$A14+Configuración!$C$7/1440)*(Escaleta!$E$5:$E$504>$A14)*ROW(Escaleta!$A$5:$A$504)))) | Q14: =IF(OR($A14="",G$6=""),0,SUMPRODUCT(MAX((Escaleta!$A$5:$A$504=$B$4)*(Escaleta!$H$5:$H$504=G$6)*(Escaleta!$K$5:$K$504<>"Cancelada")*(Escaleta!$C$5:$C$504<$A14+Configuración!$C$7/1440)*(Escaleta!$E$5:$E$504>$A14)*ROW(Escaleta!$A$5:$A$504)))) | R14: =IF(OR($A14="",H$6=""),0,SUMPRODUCT(MAX((Escaleta!$A$5:$A$504=$B$4)*(Escaleta!$H$5:$H$504=H$6)*(Escaleta!$K$5:$K$504<>"Cancelada")*(Escaleta!$C$5:$C$504<$A14+Configuración!$C$7/1440)*(Escaleta!$E$5:$E$504>$A14)*ROW(Escaleta!$A$5:$A$504)))) | S14: =IF(OR($A14="",I$6=""),0,SUMPRODUCT(MAX((Escaleta!$A$5:$A$504=$B$4)*(Escaleta!$H$5:$H$504=I$6)*(Escaleta!$K$5:$K$504<>"Cancelada")*(Escaleta!$C$5:$C$504<$A14+Configuración!$C$7/1440)*(Escaleta!$E$5:$E$504>$A14)*ROW(Escaleta!$A$5:$A$504)))) | U14: =IF(L14=0,"",INDEX(Escaleta!$I$1:$I$504,L14)) | V14: =IF(M14=0,"",INDEX(Escaleta!$I$1:$I$504,M14)) | W14: =IF(N14=0,"",INDEX(Escaleta!$I$1:$I$504,N14)) | X14: =IF(O14=0,"",INDEX(Escaleta!$I$1:$I$504,O14)) | Y14: =IF(P14=0,"",INDEX(Escaleta!$I$1:$I$504,P14)) | Z14: =IF(Q14=0,"",INDEX(Escaleta!$I$1:$I$504,Q14)) | AA14: =IF(R14=0,"",INDEX(Escaleta!$I$1:$I$504,R14)) | AB14: =IF(S14=0,"",INDEX(Escaleta!$I$1:$I$504,S14))
A15: =IF(A14="","",IF(A14+Configuración!$C$7/1440>Configuración!$C$6-0.0001,"",A14+Configuración!$C$7/1440)) | B15: =IF(L15=0,"",IF(L15<>L14,INDEX(Escaleta!$F$1:$F$504,L15),IF(L15<>L13,TEXT(INDEX(Escaleta!$C$1:$C$504,L15),"hh:mm")&"–"&TEXT(INDEX(Escaleta!$E$1:$E$504,L15),"hh:mm"),""))) | C15: =IF(M15=0,"",IF(M15<>M14,INDEX(Escaleta!$F$1:$F$504,M15),IF(M15<>M13,TEXT(INDEX(Escaleta!$C$1:$C$504,M15),"hh:mm")&"–"&TEXT(INDEX(Escaleta!$E$1:$E$504,M15),"hh:mm"),""))) | D15: =IF(N15=0,"",IF(N15<>N14,INDEX(Escaleta!$F$1:$F$504,N15),IF(N15<>N13,TEXT(INDEX(Escaleta!$C$1:$C$504,N15),"hh:mm")&"–"&TEXT(INDEX(Escaleta!$E$1:$E$504,N15),"hh:mm"),""))) | E15: =IF(O15=0,"",IF(O15<>O14,INDEX(Escaleta!$F$1:$F$504,O15),IF(O15<>O13,TEXT(INDEX(Escaleta!$C$1:$C$504,O15),"hh:mm")&"–"&TEXT(INDEX(Escaleta!$E$1:$E$504,O15),"hh:mm"),""))) | F15: =IF(P15=0,"",IF(P15<>P14,INDEX(Escaleta!$F$1:$F$504,P15),IF(P15<>P13,TEXT(INDEX(Escaleta!$C$1:$C$504,P15),"hh:mm")&"–"&TEXT(INDEX(Escaleta!$E$1:$E$504,P15),"hh:mm"),""))) | G15: =IF(Q15=0,"",IF(Q15<>Q14,INDEX(Escaleta!$F$1:$F$504,Q15),IF(Q15<>Q13,TEXT(INDEX(Escaleta!$C$1:$C$504,Q15),"hh:mm")&"–"&TEXT(INDEX(Escaleta!$E$1:$E$504,Q15),"hh:mm"),""))) | H15: =IF(R15=0,"",IF(R15<>R14,INDEX(Escaleta!$F$1:$F$504,R15),IF(R15<>R13,TEXT(INDEX(Escaleta!$C$1:$C$504,R15),"hh:mm")&"–"&TEXT(INDEX(Escaleta!$E$1:$E$504,R15),"hh:mm"),""))) | I15: =IF(S15=0,"",IF(S15<>S14,INDEX(Escaleta!$F$1:$F$504,S15),IF(S15<>S13,TEXT(INDEX(Escaleta!$C$1:$C$504,S15),"hh:mm")&"–"&TEXT(INDEX(Escaleta!$E$1:$E$504,S15),"hh:mm"),""))) | L15: =IF(OR($A15="",B$6=""),0,SUMPRODUCT(MAX((Escaleta!$A$5:$A$504=$B$4)*(Escaleta!$H$5:$H$504=B$6)*(Escaleta!$K$5:$K$504<>"Cancelada")*(Escaleta!$C$5:$C$504<$A15+Configuración!$C$7/1440)*(Escaleta!$E$5:$E$504>$A15)*ROW(Escaleta!$A$5:$A$504)))) | M15: =IF(OR($A15="",C$6=""),0,SUMPRODUCT(MAX((Escaleta!$A$5:$A$504=$B$4)*(Escaleta!$H$5:$H$504=C$6)*(Escaleta!$K$5:$K$504<>"Cancelada")*(Escaleta!$C$5:$C$504<$A15+Configuración!$C$7/1440)*(Escaleta!$E$5:$E$504>$A15)*ROW(Escaleta!$A$5:$A$504)))) | N15: =IF(OR($A15="",D$6=""),0,SUMPRODUCT(MAX((Escaleta!$A$5:$A$504=$B$4)*(Escaleta!$H$5:$H$504=D$6)*(Escaleta!$K$5:$K$504<>"Cancelada")*(Escaleta!$C$5:$C$504<$A15+Configuración!$C$7/1440)*(Escaleta!$E$5:$E$504>$A15)*ROW(Escaleta!$A$5:$A$504)))) | O15: =IF(OR($A15="",E$6=""),0,SUMPRODUCT(MAX((Escaleta!$A$5:$A$504=$B$4)*(Escaleta!$H$5:$H$504=E$6)*(Escaleta!$K$5:$K$504<>"Cancelada")*(Escaleta!$C$5:$C$504<$A15+Configuración!$C$7/1440)*(Escaleta!$E$5:$E$504>$A15)*ROW(Escaleta!$A$5:$A$504)))) | P15: =IF(OR($A15="",F$6=""),0,SUMPRODUCT(MAX((Escaleta!$A$5:$A$504=$B$4)*(Escaleta!$H$5:$H$504=F$6)*(Escaleta!$K$5:$K$504<>"Cancelada")*(Escaleta!$C$5:$C$504<$A15+Configuración!$C$7/1440)*(Escaleta!$E$5:$E$504>$A15)*ROW(Escaleta!$A$5:$A$504)))) | Q15: =IF(OR($A15="",G$6=""),0,SUMPRODUCT(MAX((Escaleta!$A$5:$A$504=$B$4)*(Escaleta!$H$5:$H$504=G$6)*(Escaleta!$K$5:$K$504<>"Cancelada")*(Escaleta!$C$5:$C$504<$A15+Configuración!$C$7/1440)*(Escaleta!$E$5:$E$504>$A15)*ROW(Escaleta!$A$5:$A$504)))) | R15: =IF(OR($A15="",H$6=""),0,SUMPRODUCT(MAX((Escaleta!$A$5:$A$504=$B$4)*(Escaleta!$H$5:$H$504=H$6)*(Escaleta!$K$5:$K$504<>"Cancelada")*(Escaleta!$C$5:$C$504<$A15+Configuración!$C$7/1440)*(Escaleta!$E$5:$E$504>$A15)*ROW(Escaleta!$A$5:$A$504)))) | S15: =IF(OR($A15="",I$6=""),0,SUMPRODUCT(MAX((Escaleta!$A$5:$A$504=$B$4)*(Escaleta!$H$5:$H$504=I$6)*(Escaleta!$K$5:$K$504<>"Cancelada")*(Escaleta!$C$5:$C$504<$A15+Configuración!$C$7/1440)*(Escaleta!$E$5:$E$504>$A15)*ROW(Escaleta!$A$5:$A$504)))) | U15: =IF(L15=0,"",INDEX(Escaleta!$I$1:$I$504,L15)) | V15: =IF(M15=0,"",INDEX(Escaleta!$I$1:$I$504,M15)) | W15: =IF(N15=0,"",INDEX(Escaleta!$I$1:$I$504,N15)) | X15: =IF(O15=0,"",INDEX(Escaleta!$I$1:$I$504,O15)) | Y15: =IF(P15=0,"",INDEX(Escaleta!$I$1:$I$504,P15)) | Z15: =IF(Q15=0,"",INDEX(Escaleta!$I$1:$I$504,Q15)) | AA15: =IF(R15=0,"",INDEX(Escaleta!$I$1:$I$504,R15)) | AB15: =IF(S15=0,"",INDEX(Escaleta!$I$1:$I$504,S15))
A16: =IF(A15="","",IF(A15+Configuración!$C$7/1440>Configuración!$C$6-0.0001,"",A15+Configuración!$C$7/1440)) | B16: =IF(L16=0,"",IF(L16<>L15,INDEX(Escaleta!$F$1:$F$504,L16),IF(L16<>L14,TEXT(INDEX(Escaleta!$C$1:$C$504,L16),"hh:mm")&"–"&TEXT(INDEX(Escaleta!$E$1:$E$504,L16),"hh:mm"),""))) | C16: =IF(M16=0,"",IF(M16<>M15,INDEX(Escaleta!$F$1:$F$504,M16),IF(M16<>M14,TEXT(INDEX(Escaleta!$C$1:$C$504,M16),"hh:mm")&"–"&TEXT(INDEX(Escaleta!$E$1:$E$504,M16),"hh:mm"),""))) | D16: =IF(N16=0,"",IF(N16<>N15,INDEX(Escaleta!$F$1:$F$504,N16),IF(N16<>N14,TEXT(INDEX(Escaleta!$C$1:$C$504,N16),"hh:mm")&"–"&TEXT(INDEX(Escaleta!$E$1:$E$504,N16),"hh:mm"),""))) | E16: =IF(O16=0,"",IF(O16<>O15,INDEX(Escaleta!$F$1:$F$504,O16),IF(O16<>O14,TEXT(INDEX(Escaleta!$C$1:$C$504,O16),"hh:mm")&"–"&TEXT(INDEX(Escaleta!$E$1:$E$504,O16),"hh:mm"),""))) | F16: =IF(P16=0,"",IF(P16<>P15,INDEX(Escaleta!$F$1:$F$504,P16),IF(P16<>P14,TEXT(INDEX(Escaleta!$C$1:$C$504,P16),"hh:mm")&"–"&TEXT(INDEX(Escaleta!$E$1:$E$504,P16),"hh:mm"),""))) | G16: =IF(Q16=0,"",IF(Q16<>Q15,INDEX(Escaleta!$F$1:$F$504,Q16),IF(Q16<>Q14,TEXT(INDEX(Escaleta!$C$1:$C$504,Q16),"hh:mm")&"–"&TEXT(INDEX(Escaleta!$E$1:$E$504,Q16),"hh:mm"),""))) | H16: =IF(R16=0,"",IF(R16<>R15,INDEX(Escaleta!$F$1:$F$504,R16),IF(R16<>R14,TEXT(INDEX(Escaleta!$C$1:$C$504,R16),"hh:mm")&"–"&TEXT(INDEX(Escaleta!$E$1:$E$504,R16),"hh:mm"),""))) | I16: =IF(S16=0,"",IF(S16<>S15,INDEX(Escaleta!$F$1:$F$504,S16),IF(S16<>S14,TEXT(INDEX(Escaleta!$C$1:$C$504,S16),"hh:mm")&"–"&TEXT(INDEX(Escaleta!$E$1:$E$504,S16),"hh:mm"),""))) | L16: =IF(OR($A16="",B$6=""),0,SUMPRODUCT(MAX((Escaleta!$A$5:$A$504=$B$4)*(Escaleta!$H$5:$H$504=B$6)*(Escaleta!$K$5:$K$504<>"Cancelada")*(Escaleta!$C$5:$C$504<$A16+Configuración!$C$7/1440)*(Escaleta!$E$5:$E$504>$A16)*ROW(Escaleta!$A$5:$A$504)))) | M16: =IF(OR($A16="",C$6=""),0,SUMPRODUCT(MAX((Escaleta!$A$5:$A$504=$B$4)*(Escaleta!$H$5:$H$504=C$6)*(Escaleta!$K$5:$K$504<>"Cancelada")*(Escaleta!$C$5:$C$504<$A16+Configuración!$C$7/1440)*(Escaleta!$E$5:$E$504>$A16)*ROW(Escaleta!$A$5:$A$504)))) | N16: =IF(OR($A16="",D$6=""),0,SUMPRODUCT(MAX((Escaleta!$A$5:$A$504=$B$4)*(Escaleta!$H$5:$H$504=D$6)*(Escaleta!$K$5:$K$504<>"Cancelada")*(Escaleta!$C$5:$C$504<$A16+Configuración!$C$7/1440)*(Escaleta!$E$5:$E$504>$A16)*ROW(Escaleta!$A$5:$A$504)))) | O16: =IF(OR($A16="",E$6=""),0,SUMPRODUCT(MAX((Escaleta!$A$5:$A$504=$B$4)*(Escaleta!$H$5:$H$504=E$6)*(Escaleta!$K$5:$K$504<>"Cancelada")*(Escaleta!$C$5:$C$504<$A16+Configuración!$C$7/1440)*(Escaleta!$E$5:$E$504>$A16)*ROW(Escaleta!$A$5:$A$504)))) | P16: =IF(OR($A16="",F$6=""),0,SUMPRODUCT(MAX((Escaleta!$A$5:$A$504=$B$4)*(Escaleta!$H$5:$H$504=F$6)*(Escaleta!$K$5:$K$504<>"Cancelada")*(Escaleta!$C$5:$C$504<$A16+Configuración!$C$7/1440)*(Escaleta!$E$5:$E$504>$A16)*ROW(Escaleta!$A$5:$A$504)))) | Q16: =IF(OR($A16="",G$6=""),0,SUMPRODUCT(MAX((Escaleta!$A$5:$A$504=$B$4)*(Escaleta!$H$5:$H$504=G$6)*(Escaleta!$K$5:$K$504<>"Cancelada")*(Escaleta!$C$5:$C$504<$A16+Configuración!$C$7/1440)*(Escaleta!$E$5:$E$504>$A16)*ROW(Escaleta!$A$5:$A$504)))) | R16: =IF(OR($A16="",H$6=""),0,SUMPRODUCT(MAX((Escaleta!$A$5:$A$504=$B$4)*(Escaleta!$H$5:$H$504=H$6)*(Escaleta!$K$5:$K$504<>"Cancelada")*(Escaleta!$C$5:$C$504<$A16+Configuración!$C$7/1440)*(Escaleta!$E$5:$E$504>$A16)*ROW(Escaleta!$A$5:$A$504)))) | S16: =IF(OR($A16="",I$6=""),0,SUMPRODUCT(MAX((Escaleta!$A$5:$A$504=$B$4)*(Escaleta!$H$5:$H$504=I$6)*(Escaleta!$K$5:$K$504<>"Cancelada")*(Escaleta!$C$5:$C$504<$A16+Configuración!$C$7/1440)*(Escaleta!$E$5:$E$504>$A16)*ROW(Escaleta!$A$5:$A$504)))) | U16: =IF(L16=0,"",INDEX(Escaleta!$I$1:$I$504,L16)) | V16: =IF(M16=0,"",INDEX(Escaleta!$I$1:$I$504,M16)) | W16: =IF(N16=0,"",INDEX(Escaleta!$I$1:$I$504,N16)) | X16: =IF(O16=0,"",INDEX(Escaleta!$I$1:$I$504,O16)) | Y16: =IF(P16=0,"",INDEX(Escaleta!$I$1:$I$504,P16)) | Z16: =IF(Q16=0,"",INDEX(Escaleta!$I$1:$I$504,Q16)) | AA16: =IF(R16=0,"",INDEX(Escaleta!$I$1:$I$504,R16)) | AB16: =IF(S16=0,"",INDEX(Escaleta!$I$1:$I$504,S16))
A17: =IF(A16="","",IF(A16+Configuración!$C$7/1440>Configuración!$C$6-0.0001,"",A16+Configuración!$C$7/1440)) | B17: =IF(L17=0,"",IF(L17<>L16,INDEX(Escaleta!$F$1:$F$504,L17),IF(L17<>L15,TEXT(INDEX(Escaleta!$C$1:$C$504,L17),"hh:mm")&"–"&TEXT(INDEX(Escaleta!$E$1:$E$504,L17),"hh:mm"),""))) | C17: =IF(M17=0,"",IF(M17<>M16,INDEX(Escaleta!$F$1:$F$504,M17),IF(M17<>M15,TEXT(INDEX(Escaleta!$C$1:$C$504,M17),"hh:mm")&"–"&TEXT(INDEX(Escaleta!$E$1:$E$504,M17),"hh:mm"),""))) | D17: =IF(N17=0,"",IF(N17<>N16,INDEX(Escaleta!$F$1:$F$504,N17),IF(N17<>N15,TEXT(INDEX(Escaleta!$C$1:$C$504,N17),"hh:mm")&"–"&TEXT(INDEX(Escaleta!$E$1:$E$504,N17),"hh:mm"),""))) | E17: =IF(O17=0,"",IF(O17<>O16,INDEX(Escaleta!$F$1:$F$504,O17),IF(O17<>O15,TEXT(INDEX(Escaleta!$C$1:$C$504,O17),"hh:mm")&"–"&TEXT(INDEX(Escaleta!$E$1:$E$504,O17),"hh:mm"),""))) | F17: =IF(P17=0,"",IF(P17<>P16,INDEX(Escaleta!$F$1:$F$504,P17),IF(P17<>P15,TEXT(INDEX(Escaleta!$C$1:$C$504,P17),"hh:mm")&"–"&TEXT(INDEX(Escaleta!$E$1:$E$504,P17),"hh:mm"),""))) | G17: =IF(Q17=0,"",IF(Q17<>Q16,INDEX(Escaleta!$F$1:$F$504,Q17),IF(Q17<>Q15,TEXT(INDEX(Escaleta!$C$1:$C$504,Q17),"hh:mm")&"–"&TEXT(INDEX(Escaleta!$E$1:$E$504,Q17),"hh:mm"),""))) | H17: =IF(R17=0,"",IF(R17<>R16,INDEX(Escaleta!$F$1:$F$504,R17),IF(R17<>R15,TEXT(INDEX(Escaleta!$C$1:$C$504,R17),"hh:mm")&"–"&TEXT(INDEX(Escaleta!$E$1:$E$504,R17),"hh:mm"),""))) | I17: =IF(S17=0,"",IF(S17<>S16,INDEX(Escaleta!$F$1:$F$504,S17),IF(S17<>S15,TEXT(INDEX(Escaleta!$C$1:$C$504,S17),"hh:mm")&"–"&TEXT(INDEX(Escaleta!$E$1:$E$504,S17),"hh:mm"),""))) | L17: =IF(OR($A17="",B$6=""),0,SUMPRODUCT(MAX((Escaleta!$A$5:$A$504=$B$4)*(Escaleta!$H$5:$H$504=B$6)*(Escaleta!$K$5:$K$504<>"Cancelada")*(Escaleta!$C$5:$C$504<$A17+Configuración!$C$7/1440)*(Escaleta!$E$5:$E$504>$A17)*ROW(Escaleta!$A$5:$A$504)))) | M17: =IF(OR($A17="",C$6=""),0,SUMPRODUCT(MAX((Escaleta!$A$5:$A$504=$B$4)*(Escaleta!$H$5:$H$504=C$6)*(Escaleta!$K$5:$K$504<>"Cancelada")*(Escaleta!$C$5:$C$504<$A17+Configuración!$C$7/1440)*(Escaleta!$E$5:$E$504>$A17)*ROW(Escaleta!$A$5:$A$504)))) | N17: =IF(OR($A17="",D$6=""),0,SUMPRODUCT(MAX((Escaleta!$A$5:$A$504=$B$4)*(Escaleta!$H$5:$H$504=D$6)*(Escaleta!$K$5:$K$504<>"Cancelada")*(Escaleta!$C$5:$C$504<$A17+Configuración!$C$7/1440)*(Escaleta!$E$5:$E$504>$A17)*ROW(Escaleta!$A$5:$A$504)))) | O17: =IF(OR($A17="",E$6=""),0,SUMPRODUCT(MAX((Escaleta!$A$5:$A$504=$B$4)*(Escaleta!$H$5:$H$504=E$6)*(Escaleta!$K$5:$K$504<>"Cancelada")*(Escaleta!$C$5:$C$504<$A17+Configuración!$C$7/1440)*(Escaleta!$E$5:$E$504>$A17)*ROW(Escaleta!$A$5:$A$504)))) | P17: =IF(OR($A17="",F$6=""),0,SUMPRODUCT(MAX((Escaleta!$A$5:$A$504=$B$4)*(Escaleta!$H$5:$H$504=F$6)*(Escaleta!$K$5:$K$504<>"Cancelada")*(Escaleta!$C$5:$C$504<$A17+Configuración!$C$7/1440)*(Escaleta!$E$5:$E$504>$A17)*ROW(Escaleta!$A$5:$A$504)))) | Q17: =IF(OR($A17="",G$6=""),0,SUMPRODUCT(MAX((Escaleta!$A$5:$A$504=$B$4)*(Escaleta!$H$5:$H$504=G$6)*(Escaleta!$K$5:$K$504<>"Cancelada")*(Escaleta!$C$5:$C$504<$A17+Configuración!$C$7/1440)*(Escaleta!$E$5:$E$504>$A17)*ROW(Escaleta!$A$5:$A$504)))) | R17: =IF(OR($A17="",H$6=""),0,SUMPRODUCT(MAX((Escaleta!$A$5:$A$504=$B$4)*(Escaleta!$H$5:$H$504=H$6)*(Escaleta!$K$5:$K$504<>"Cancelada")*(Escaleta!$C$5:$C$504<$A17+Configuración!$C$7/1440)*(Escaleta!$E$5:$E$504>$A17)*ROW(Escaleta!$A$5:$A$504)))) | S17: =IF(OR($A17="",I$6=""),0,SUMPRODUCT(MAX((Escaleta!$A$5:$A$504=$B$4)*(Escaleta!$H$5:$H$504=I$6)*(Escaleta!$K$5:$K$504<>"Cancelada")*(Escaleta!$C$5:$C$504<$A17+Configuración!$C$7/1440)*(Escaleta!$E$5:$E$504>$A17)*ROW(Escaleta!$A$5:$A$504)))) | U17: =IF(L17=0,"",INDEX(Escaleta!$I$1:$I$504,L17)) | V17: =IF(M17=0,"",INDEX(Escaleta!$I$1:$I$504,M17)) | W17: =IF(N17=0,"",INDEX(Escaleta!$I$1:$I$504,N17)) | X17: =IF(O17=0,"",INDEX(Escaleta!$I$1:$I$504,O17)) | Y17: =IF(P17=0,"",INDEX(Escaleta!$I$1:$I$504,P17)) | Z17: =IF(Q17=0,"",INDEX(Escaleta!$I$1:$I$504,Q17)) | AA17: =IF(R17=0,"",INDEX(Escaleta!$I$1:$I$504,R17)) | AB17: =IF(S17=0,"",INDEX(Escaleta!$I$1:$I$504,S17))
A18: =IF(A17="","",IF(A17+Configuración!$C$7/1440>Configuración!$C$6-0.0001,"",A17+Configuración!$C$7/1440)) | B18: =IF(L18=0,"",IF(L18<>L17,INDEX(Escaleta!$F$1:$F$504,L18),IF(L18<>L16,TEXT(INDEX(Escaleta!$C$1:$C$504,L18),"hh:mm")&"–"&TEXT(INDEX(Escaleta!$E$1:$E$504,L18),"hh:mm"),""))) | C18: =IF(M18=0,"",IF(M18<>M17,INDEX(Escaleta!$F$1:$F$504,M18),IF(M18<>M16,TEXT(INDEX(Escaleta!$C$1:$C$504,M18),"hh:mm")&"–"&TEXT(INDEX(Escaleta!$E$1:$E$504,M18),"hh:mm"),""))) | D18: =IF(N18=0,"",IF(N18<>N17,INDEX(Escaleta!$F$1:$F$504,N18),IF(N18<>N16,TEXT(INDEX(Escaleta!$C$1:$C$504,N18),"hh:mm")&"–"&TEXT(INDEX(Escaleta!$E$1:$E$504,N18),"hh:mm"),""))) | E18: =IF(O18=0,"",IF(O18<>O17,INDEX(Escaleta!$F$1:$F$504,O18),IF(O18<>O16,TEXT(INDEX(Escaleta!$C$1:$C$504,O18),"hh:mm")&"–"&TEXT(INDEX(Escaleta!$E$1:$E$504,O18),"hh:mm"),""))) | F18: =IF(P18=0,"",IF(P18<>P17,INDEX(Escaleta!$F$1:$F$504,P18),IF(P18<>P16,TEXT(INDEX(Escaleta!$C$1:$C$504,P18),"hh:mm")&"–"&TEXT(INDEX(Escaleta!$E$1:$E$504,P18),"hh:mm"),""))) | G18: =IF(Q18=0,"",IF(Q18<>Q17,INDEX(Escaleta!$F$1:$F$504,Q18),IF(Q18<>Q16,TEXT(INDEX(Escaleta!$C$1:$C$504,Q18),"hh:mm")&"–"&TEXT(INDEX(Escaleta!$E$1:$E$504,Q18),"hh:mm"),""))) | H18: =IF(R18=0,"",IF(R18<>R17,INDEX(Escaleta!$F$1:$F$504,R18),IF(R18<>R16,TEXT(INDEX(Escaleta!$C$1:$C$504,R18),"hh:mm")&"–"&TEXT(INDEX(Escaleta!$E$1:$E$504,R18),"hh:mm"),""))) | I18: =IF(S18=0,"",IF(S18<>S17,INDEX(Escaleta!$F$1:$F$504,S18),IF(S18<>S16,TEXT(INDEX(Escaleta!$C$1:$C$504,S18),"hh:mm")&"–"&TEXT(INDEX(Escaleta!$E$1:$E$504,S18),"hh:mm"),""))) | L18: =IF(OR($A18="",B$6=""),0,SUMPRODUCT(MAX((Escaleta!$A$5:$A$504=$B$4)*(Escaleta!$H$5:$H$504=B$6)*(Escaleta!$K$5:$K$504<>"Cancelada")*(Escaleta!$C$5:$C$504<$A18+Configuración!$C$7/1440)*(Escaleta!$E$5:$E$504>$A18)*ROW(Escaleta!$A$5:$A$504)))) | M18: =IF(OR($A18="",C$6=""),0,SUMPRODUCT(MAX((Escaleta!$A$5:$A$504=$B$4)*(Escaleta!$H$5:$H$504=C$6)*(Escaleta!$K$5:$K$504<>"Cancelada")*(Escaleta!$C$5:$C$504<$A18+Configuración!$C$7/1440)*(Escaleta!$E$5:$E$504>$A18)*ROW(Escaleta!$A$5:$A$504)))) | N18: =IF(OR($A18="",D$6=""),0,SUMPRODUCT(MAX((Escaleta!$A$5:$A$504=$B$4)*(Escaleta!$H$5:$H$504=D$6)*(Escaleta!$K$5:$K$504<>"Cancelada")*(Escaleta!$C$5:$C$504<$A18+Configuración!$C$7/1440)*(Escaleta!$E$5:$E$504>$A18)*ROW(Escaleta!$A$5:$A$504)))) | O18: =IF(OR($A18="",E$6=""),0,SUMPRODUCT(MAX((Escaleta!$A$5:$A$504=$B$4)*(Escaleta!$H$5:$H$504=E$6)*(Escaleta!$K$5:$K$504<>"Cancelada")*(Escaleta!$C$5:$C$504<$A18+Configuración!$C$7/1440)*(Escaleta!$E$5:$E$504>$A18)*ROW(Escaleta!$A$5:$A$504)))) | P18: =IF(OR($A18="",F$6=""),0,SUMPRODUCT(MAX((Escaleta!$A$5:$A$504=$B$4)*(Escaleta!$H$5:$H$504=F$6)*(Escaleta!$K$5:$K$504<>"Cancelada")*(Escaleta!$C$5:$C$504<$A18+Configuración!$C$7/1440)*(Escaleta!$E$5:$E$504>$A18)*ROW(Escaleta!$A$5:$A$504)))) | Q18: =IF(OR($A18="",G$6=""),0,SUMPRODUCT(MAX((Escaleta!$A$5:$A$504=$B$4)*(Escaleta!$H$5:$H$504=G$6)*(Escaleta!$K$5:$K$504<>"Cancelada")*(Escaleta!$C$5:$C$504<$A18+Configuración!$C$7/1440)*(Escaleta!$E$5:$E$504>$A18)*ROW(Escaleta!$A$5:$A$504)))) | R18: =IF(OR($A18="",H$6=""),0,SUMPRODUCT(MAX((Escaleta!$A$5:$A$504=$B$4)*(Escaleta!$H$5:$H$504=H$6)*(Escaleta!$K$5:$K$504<>"Cancelada")*(Escaleta!$C$5:$C$504<$A18+Configuración!$C$7/1440)*(Escaleta!$E$5:$E$504>$A18)*ROW(Escaleta!$A$5:$A$504)))) | S18: =IF(OR($A18="",I$6=""),0,SUMPRODUCT(MAX((Escaleta!$A$5:$A$504=$B$4)*(Escaleta!$H$5:$H$504=I$6)*(Escaleta!$K$5:$K$504<>"Cancelada")*(Escaleta!$C$5:$C$504<$A18+Configuración!$C$7/1440)*(Escaleta!$E$5:$E$504>$A18)*ROW(Escaleta!$A$5:$A$504)))) | U18: =IF(L18=0,"",INDEX(Escaleta!$I$1:$I$504,L18)) | V18: =IF(M18=0,"",INDEX(Escaleta!$I$1:$I$504,M18)) | W18: =IF(N18=0,"",INDEX(Escaleta!$I$1:$I$504,N18)) | X18: =IF(O18=0,"",INDEX(Escaleta!$I$1:$I$504,O18)) | Y18: =IF(P18=0,"",INDEX(Escaleta!$I$1:$I$504,P18)) | Z18: =IF(Q18=0,"",INDEX(Escaleta!$I$1:$I$504,Q18)) | AA18: =IF(R18=0,"",INDEX(Escaleta!$I$1:$I$504,R18)) | AB18: =IF(S18=0,"",INDEX(Escaleta!$I$1:$I$504,S18))
